Workbook
Name cfgBodega: '01_CONFIG'!$C$11
Name cfgDiasSinRotacion: '01_CONFIG'!$C$14
Name cfgEdicion: '01_CONFIG'!$C$17
Name cfgEmpresa: '01_CONFIG'!$C$9
Name cfgFechaBuild: '01_CONFIG'!$C$18
Name cfgFechaMin: '01_CONFIG'!$C$15
Name cfgMargenAlerta: '01_CONFIG'!$C$13
Name cfgMoneda: '01_CONFIG'!$C$12
Name cfgNIT: '01_CONFIG'!$C$10
Name cfgProveedor: '01_CONFIG'!$C$19
Name cfgSelladoHasta: '01_CONFIG'!$C$20
Name cfgVersion: '01_CONFIG'!$C$16
Name ctFecha: '13_CONTEO'!$K$5
Name ctResponsable: '13_CONTEO'!$M$5
Name irBitacora: INDEX('10_MOVIMIENTOS'!$C:$C,MIN(kpiFilaLibreMov,5007))
Name irConsultar: '17_KARDEX'!$H$8
Name irFilaLibreProd: INDEX('05_PRODUCTOS'!$B:$B,MIN(kpiFilaLibreProd,507))
Name irFilaLibreProv: INDEX('04_PROVEEDORES'!$B:$B,MIN(kpiFilaLibreProv,107))
Name irPrimerAdvertencia: INDEX(tblMovimientos[Fecha],MATCH("⚠*",tblMovimientos[Estado],0))
Name irPrimerError: INDEX(tblMovimientos[Fecha],MATCH("✖*",tblMovimientos[Estado],0))
Name irPrimerosPasos: '99_AYUDA'!$B$9
Name irRegistrar: irBitacora
Name irSiguientePaso: CHOOSE(kpiPaso,irPrimerError,irPrimerosPasos,irFilaLibreProd,irRegistrar,irPrimerAdvertencia,'13_CONTEO'!$I$8,'18_PEDIDO'!$D$10,'18_PEDIDO'!$D$10,'15_STOCK'!$A$1,'15_STOCK'!$A$1)
Name kpiActivos: '91_KPIS'!$C$9
Name kpiAdvertencias: '91_KPIS'!$C$34
Name kpiAgotados: '91_KPIS'!$C$11
Name kpiBajos: '91_KPIS'!$C$13
Name kpiCapacidad: '91_KPIS'!$C$24
Name kpiCatalogo: '91_KPIS'!$C$8
Name kpiCategorias: '91_KPIS'!$C$22
Name kpiConSaldoInicial: '91_KPIS'!$C$35
Name kpiConteoContados: '91_KPIS'!$C$37
Name kpiConteoDif: '91_KPIS'!$C$38
Name kpiConteoValor: '91_KPIS'!$C$39
Name kpiCriticos: '91_KPIS'!$C$12
Name kpiEgrMes: '91_KPIS'!$C$31
Name kpiEnAlerta: '91_KPIS'!$C$17
Name kpiErrores: '91_KPIS'!$C$33
Name kpiFilaLibreMov: '91_KPIS'!$C$26
Name kpiFilaLibreProd: '91_KPIS'!$C$27
Name kpiFilaLibreProv: '91_KPIS'!$C$28
Name kpiInactivos: '91_KPIS'!$C$16
Name kpiInconsistentes: '91_KPIS'!$C$10
Name kpiIngMes: '91_KPIS'!$C$30
Name kpiMovMes: '91_KPIS'!$C$29
Name kpiOperativos: '91_KPIS'!$C$36
Name kpiOptimos: '91_KPIS'!$C$14
Name kpiPaso: '91_KPIS'!$C$51
Name kpiPasoNivel: '91_KPIS'!$C$52
Name kpiPedidoLineas: '91_KPIS'!$C$41
Name kpiPedidoProv: '91_KPIS'!$C$43
Name kpiPedidoTotal: '91_KPIS'!$C$42
Name kpiProveedores: '91_KPIS'!$C$21
Name kpiRegistros: '91_KPIS'!$C$23
Name kpiSinRotacion: '91_KPIS'!$C$19
Name kpiSobrestock: '91_KPIS'!$C$15
Name kpiUltFecha: '91_KPIS'!$C$32
Name kpiUltimoID: '91_KPIS'!$C$25
Name kpiValor: '91_KPIS'!$C$18
Name kpiValorSinRot: '91_KPIS'!$C$20

Sheet 00_PORTADA
D2: M-INV · Sistema de Inventarios | J2: =TODAY() -> 46290
D3: =txtEmpresa -> NOMBRE DE SU EMPRESA · Bodega principal | J3: M-INV V1.2.0
B6: PRÓXIMO PASO | C6: =txtPaso -> ① Primeros pasos: el administrador debe personalizar el nombre de la empresa y las categorías.
B10: ▍ INDICADORES CLAVE | J10: =txtIntegridad -> ✔ Bitácora íntegra · sin errores
B15: ▍ ANÁLISIS DEL INVENTARIO
B19: ▍ ÚLTIMOS MOVIMIENTOS
B20: Fecha | C20: Tipo | D20: Producto | I20: Cantidad | J20: Unidad | K20: Responsable | M20: Documento
B21: =IF(kpiUltimoID-0<1,"",INDEX(tblMovimientos[Fecha],kpiUltimoID-0)) | C21: =IF(kpiUltimoID-0<1,"",INDEX(tblMovimientos[Tipo],kpiUltimoID-0)&"") | D21: =IF(kpiUltimoID-0<1,"",INDEX(tblMovimientos[Producto],kpiUltimoID-0)&"") | I21: =IF(kpiUltimoID-0<1,"",INDEX(tblMovimientos[CantidadNeta],kpiUltimoID-0)) | J21: =IF(kpiUltimoID-0<1,"",INDEX(tblMovimientos[Unidad],kpiUltimoID-0)&"") | K21: =IF(kpiUltimoID-0<1,"",INDEX(tblMovimientos[Responsable],kpiUltimoID-0)&"") | M21: =IF(kpiUltimoID-0<1,"",INDEX(tblMovimientos[Documento],kpiUltimoID-0)&"")
B22: =IF(kpiUltimoID-1<1,"",INDEX(tblMovimientos[Fecha],kpiUltimoID-1)) | C22: =IF(kpiUltimoID-1<1,"",INDEX(tblMovimientos[Tipo],kpiUltimoID-1)&"") | D22: =IF(kpiUltimoID-1<1,"",INDEX(tblMovimientos[Producto],kpiUltimoID-1)&"") | I22: =IF(kpiUltimoID-1<1,"",INDEX(tblMovimientos[CantidadNeta],kpiUltimoID-1)) | J22: =IF(kpiUltimoID-1<1,"",INDEX(tblMovimientos[Unidad],kpiUltimoID-1)&"") | K22: =IF(kpiUltimoID-1<1,"",INDEX(tblMovimientos[Responsable],kpiUltimoID-1)&"") | M22: =IF(kpiUltimoID-1<1,"",INDEX(tblMovimientos[Documento],kpiUltimoID-1)&"")
B23: =IF(kpiUltimoID-2<1,"",INDEX(tblMovimientos[Fecha],kpiUltimoID-2)) | C23: =IF(kpiUltimoID-2<1,"",INDEX(tblMovimientos[Tipo],kpiUltimoID-2)&"") | D23: =IF(kpiUltimoID-2<1,"",INDEX(tblMovimientos[Producto],kpiUltimoID-2)&"") | I23: =IF(kpiUltimoID-2<1,"",INDEX(tblMovimientos[CantidadNeta],kpiUltimoID-2)) | J23: =IF(kpiUltimoID-2<1,"",INDEX(tblMovimientos[Unidad],kpiUltimoID-2)&"") | K23: =IF(kpiUltimoID-2<1,"",INDEX(tblMovimientos[Responsable],kpiUltimoID-2)&"") | M23: =IF(kpiUltimoID-2<1,"",INDEX(tblMovimientos[Documento],kpiUltimoID-2)&"")
B24: =IF(kpiUltimoID-3<1,"",INDEX(tblMovimientos[Fecha],kpiUltimoID-3)) | C24: =IF(kpiUltimoID-3<1,"",INDEX(tblMovimientos[Tipo],kpiUltimoID-3)&"") | D24: =IF(kpiUltimoID-3<1,"",INDEX(tblMovimientos[Producto],kpiUltimoID-3)&"") | I24: =IF(kpiUltimoID-3<1,"",INDEX(tblMovimientos[CantidadNeta],kpiUltimoID-3)) | J24: =IF(kpiUltimoID-3<1,"",INDEX(tblMovimientos[Unidad],kpiUltimoID-3)&"") | K24: =IF(kpiUltimoID-3<1,"",INDEX(tblMovimientos[Responsable],kpiUltimoID-3)&"") | M24: =IF(kpiUltimoID-3<1,"",INDEX(tblMovimientos[Documento],kpiUltimoID-3)&"")
B25: =IF(kpiUltimoID-4<1,"",INDEX(tblMovimientos[Fecha],kpiUltimoID-4)) | C25: =IF(kpiUltimoID-4<1,"",INDEX(tblMovimientos[Tipo],kpiUltimoID-4)&"") | D25: =IF(kpiUltimoID-4<1,"",INDEX(tblMovimientos[Producto],kpiUltimoID-4)&"") | I25: =IF(kpiUltimoID-4<1,"",INDEX(tblMovimientos[CantidadNeta],kpiUltimoID-4)) | J25: =IF(kpiUltimoID-4<1,"",INDEX(tblMovimientos[Unidad],kpiUltimoID-4)&"") | K25: =IF(kpiUltimoID-4<1,"",INDEX(tblMovimientos[Responsable],kpiUltimoID-4)&"") | M25: =IF(kpiUltimoID-4<1,"",INDEX(tblMovimientos[Documento],kpiUltimoID-4)&"")
B26: =IF(kpiUltimoID-5<1,"",INDEX(tblMovimientos[Fecha],kpiUltimoID-5)) | C26: =IF(kpiUltimoID-5<1,"",INDEX(tblMovimientos[Tipo],kpiUltimoID-5)&"") | D26: =IF(kpiUltimoID-5<1,"",INDEX(tblMovimientos[Producto],kpiUltimoID-5)&"") | I26: =IF(kpiUltimoID-5<1,"",INDEX(tblMovimientos[CantidadNeta],kpiUltimoID-5)) | J26: =IF(kpiUltimoID-5<1,"",INDEX(tblMovimientos[Unidad],kpiUltimoID-5)&"") | K26: =IF(kpiUltimoID-5<1,"",INDEX(tblMovimientos[Responsable],kpiUltimoID-5)&"") | M26: =IF(kpiUltimoID-5<1,"",INDEX(tblMovimientos[Documento],kpiUltimoID-5)&"")
B27: =IF(kpiUltimoID-6<1,"",INDEX(tblMovimientos[Fecha],kpiUltimoID-6)) | C27: =IF(kpiUltimoID-6<1,"",INDEX(tblMovimientos[Tipo],kpiUltimoID-6)&"") | D27: =IF(kpiUltimoID-6<1,"",INDEX(tblMovimientos[Producto],kpiUltimoID-6)&"") | I27: =IF(kpiUltimoID-6<1,"",INDEX(tblMovimientos[CantidadNeta],kpiUltimoID-6)) | J27: =IF(kpiUltimoID-6<1,"",INDEX(tblMovimientos[Unidad],kpiUltimoID-6)&"") | K27: =IF(kpiUltimoID-6<1,"",INDEX(tblMovimientos[Responsable],kpiUltimoID-6)&"") | M27: =IF(kpiUltimoID-6<1,"",INDEX(tblMovimientos[Documento],kpiUltimoID-6)&"")
B28: =IF(kpiUltimoID-7<1,"",INDEX(tblMovimientos[Fecha],kpiUltimoID-7)) | C28: =IF(kpiUltimoID-7<1,"",INDEX(tblMovimientos[Tipo],kpiUltimoID-7)&"") | D28: =IF(kpiUltimoID-7<1,"",INDEX(tblMovimientos[Producto],kpiUltimoID-7)&"") | I28: =IF(kpiUltimoID-7<1,"",INDEX(tblMovimientos[CantidadNeta],kpiUltimoID-7)) | J28: =IF(kpiUltimoID-7<1,"",INDEX(tblMovimientos[Unidad],kpiUltimoID-7)&"") | K28: =IF(kpiUltimoID-7<1,"",INDEX(tblMovimientos[Responsable],kpiUltimoID-7)&"") | M28: =IF(kpiUltimoID-7<1,"",INDEX(tblMovimientos[Documento],kpiUltimoID-7)&"")
B30: M-INV V1.2.0 · CQRS: escritura en 10_MOVIMIENTOS → lectura en 15_STOCK y 16_ALERTAS · Z&P Software Fast Solutions | J30: =txtBitacora -> Bitácora: 0 de 5.000 registros · 0% de capacidad

Sheet 01_CONFIG
B2: Configuración del sistema
B3: Capa de configuración (oculta) · Solo administrador · Cambios aquí afectan todo el libro
B7: PARÁMETROS DEL TENANT
B8: Parámetro | C8: Valor | D8: Descripción
B9: Empresa (cliente) | C9: NOMBRE DE SU EMPRESA | D9: Nombre que aparece en la portada y en los documentos.
B10: NIT / Identificación | D10: Identificación tributaria del cliente.
B11: Sede / Bodega | C11: Bodega principal | D11: Ubicación física que controla este libro (un libro por bodega en V1).
B12: Moneda | C12: COP | D12: Informativo. Los formatos de valor usan el símbolo $.
B13: Margen de alerta preventiva | C13: 0.2 | D13: Un producto pasa a BAJO cuando su stock es ≤ Mínimo × (1 + margen).
B14: Días para considerar sin rotación | C14: 60 | D14: Productos con stock y sin movimientos en este plazo se marcan como inventario inmovilizado.
B15: Fecha mínima permitida | C15: 43831 | D15: Fechas anteriores son rechazadas por la validación de la bitácora y del formulario.
B16: Versión del sistema | C16: 1.2.0 | D16: Versión del motor M-INV.
B17: Edición | C17: Estándar | D17: Estándar = .xlsx sin macros · Plus = .xlsm con formulario guiado y automatizaciones.
B18: Fecha de generación | C18: 46290 | D18: Fecha en que se generó este libro.
B19: Implementado por | C19: Z&P Software Fast Solutions | D19: Proveedor del software.
B20: Bitácora sellada hasta el ID | C20: 0 | D20: Lo actualiza la edición Plus al sellar registros (no editar a mano).
B22: TIPOS DE MOVIMIENTO (definen el FactorStock de la bitácora)
B23: Tipo | C23: FactorStock | D23: Descripción
B24: SALDO INICIAL | C24: 1 | D24: Carga del inventario existente al implementar el sistema (una vez por producto).
B25: ENTRADA | C25: 1 | D25: Compra, recepción de mercancía o devolución de un cliente.
B26: SALIDA | C26: -1 | D26: Venta, despacho a cliente o consumo interno.
B27: AJUSTE (+) | C27: 1 | D27: Sobrante encontrado en conteo físico. Exige observación.
B28: AJUSTE (-) | C28: -1 | D28: Merma, daño, pérdida o faltante en conteo físico. Exige observación.
B30: SEMÁFORO DE STOCK (reglas de 15_STOCK, 16_ALERTAS y 18_PEDIDO)
B31: Estado | C31: Prioridad | D31: Regla | E31: Acción
B32: INCONSISTENTE | C32: 1 | D32: Stock negativo: se registraron salidas mayores a lo disponible. | E32: Auditar la bitácora y registrar un AJUSTE
B33: AGOTADO | C33: 2 | D33: Stock en cero. | E33: Reabastecer de inmediato
B34: CRÍTICO | C34: 3 | D34: Stock en o por debajo del mínimo. | E34: Emitir orden de compra
B35: BAJO | C35: 4 | D35: Stock cercano al mínimo (dentro del margen de alerta). | E35: Programar reposición
B36: ÓPTIMO | C36: 5 | D36: Stock entre el margen de alerta y el máximo. | E36: Sin acción
B37: SOBRESTOCK | C37: 6 | D37: Stock por encima del máximo. | E37: Frenar compras / rotar inventario
B38: INACTIVO | C38: 7 | D38: Producto descontinuado (Activo = NO). | E38: Sin acción
B40: RESPONSABLES (listas de la bitácora, el formulario y la toma física)
B41: Nombre | C41: Cargo
B42: ADMINISTRADOR | C42: Administrador del sistema
B43: BODEGA | C43: Operador de bodega
B44: COMPRAS | C44: Responsable de compras

Sheet 03_CATEGORIAS
B2: Categorías
B3: Capa de configuración (oculta) · Primer nivel de la lista en cascada
B7: Código | C7: Categoría | D7: Descripción
B8: MP | C8: MATERIA PRIMA | D8: Insumos que se transforman en producto
B9: PT | C9: PRODUCTO TERMINADO | D9: Artículos listos para la venta
B10: INS | C10: INSUMOS | D10: Materiales de consumo de la operación
B11: REP | C11: REPUESTOS | D11: Partes y repuestos de mantenimiento
B12: EMP | C12: EMPAQUES | D12: Material de empaque y embalaje
B13: GEN | C13: GENERAL | D13: Artículos sin categoría específica

Sheet 04_PROVEEDORES
B2: Proveedores
B3: Datos maestros · Quién le vende cada producto y en cuántos días entrega
B6: ✎ | C6: ✎ | D6: ✎ | E6: ✎ | F6: ✎ | G6: ✎ | H6: ƒx | I6: ƒx | J6: ƒx
B7: Proveedor | C7: NIT | D7: Contacto | E7: Teléfono | F7: Correo | G7: DiasEntrega | H7: Productos | I7: EnAlerta | J7: Validación
H8: =IF(tblProveedores[[#This Row],[Proveedor]]="","",COUNTIF(tblProductos[Proveedor],tblProveedores[[#This Row],[Proveedor]])) | I8: =IF(tblProveedores[[#This Row],[Proveedor]]="","",SUMPRODUCT(COUNTIFS(tblStock[Proveedor],tblProveedores[[#This Row],[Proveedor]],tblStock[Estado],{"INCONSISTENTE","AGOTADO","CRÍTICO","BAJO"}))) | J8: =IF(AND(tblProveedores[[#This Row],[Proveedor]]="",tblProveedores[[#This Row],[NIT]]="",tblProveedores[[#This Row],[Contacto]]="",tblProveedores[[#This Row],[Correo]]=""),"",IF(tblProveedores[[#This Row],[Proveedor]]="","⚠ Falta el nombre",IF(COUNTIF(tblProveedores[Proveedor],tblProveedores[[#This Row],[Proveedor]])>1,"✖ Proveedor duplicado",IF(AND(tblProveedores[[#This Row],[Correo]]<>"",ISERROR(FIND("@",tblProveedores[[#This Row],[Correo]]))),"⚠ Correo no válido","✔ OK"))))
H9: =IF(tblProveedores[[#This Row],[Proveedor]]="","",COUNTIF(tblProductos[Proveedor],tblProveedores[[#This Row],[Proveedor]])) | I9: =IF(tblProveedores[[#This Row],[Proveedor]]="","",SUMPRODUCT(COUNTIFS(tblStock[Proveedor],tblProveedores[[#This Row],[Proveedor]],tblStock[Estado],{"INCONSISTENTE","AGOTADO","CRÍTICO","BAJO"}))) | J9: =IF(AND(tblProveedores[[#This Row],[Proveedor]]="",tblProveedores[[#This Row],[NIT]]="",tblProveedores[[#This Row],[Contacto]]="",tblProveedores[[#This Row],[Correo]]=""),"",IF(tblProveedores[[#This Row],[Proveedor]]="","⚠ Falta el nombre",IF(COUNTIF(tblProveedores[Proveedor],tblProveedores[[#This Row],[Proveedor]])>1,"✖ Proveedor duplicado",IF(AND(tblProveedores[[#This Row],[Correo]]<>"",ISERROR(FIND("@",tblProveedores[[#This Row],[Correo]]))),"⚠ Correo no válido","✔ OK"))))
H10: =IF(tblProveedores[[#This Row],[Proveedor]]="","",COUNTIF(tblProductos[Proveedor],tblProveedores[[#This Row],[Proveedor]])) | I10: =IF(tblProveedores[[#This Row],[Proveedor]]="","",SUMPRODUCT(COUNTIFS(tblStock[Proveedor],tblProveedores[[#This Row],[Proveedor]],tblStock[Estado],{"INCONSISTENTE","AGOTADO","CRÍTICO","BAJO"}))) | J10: =IF(AND(tblProveedores[[#This Row],[Proveedor]]="",tblProveedores[[#This Row],[NIT]]="",tblProveedores[[#This Row],[Contacto]]="",tblProveedores[[#This Row],[Correo]]=""),"",IF(tblProveedores[[#This Row],[Proveedor]]="","⚠ Falta el nombre",IF(COUNTIF(tblProveedores[Proveedor],tblProveedores[[#This Row],[Proveedor]])>1,"✖ Proveedor duplicado",IF(AND(tblProveedores[[#This Row],[Correo]]<>"",ISERROR(FIND("@",tblProveedores[[#This Row],[Correo]]))),"⚠ Correo no válido","✔ OK"))))
H11: =IF(tblProveedores[[#This Row],[Proveedor]]="","",COUNTIF(tblProductos[Proveedor],tblProveedores[[#This Row],[Proveedor]])) | I11: =IF(tblProveedores[[#This Row],[Proveedor]]="","",SUMPRODUCT(COUNTIFS(tblStock[Proveedor],tblProveedores[[#This Row],[Proveedor]],tblStock[Estado],{"INCONSISTENTE","AGOTADO","CRÍTICO","BAJO"}))) | J11: =IF(AND(tblProveedores[[#This Row],[Proveedor]]="",tblProveedores[[#This Row],[NIT]]="",tblProveedores[[#This Row],[Contacto]]="",tblProveedores[[#This Row],[Correo]]=""),"",IF(tblProveedores[[#This Row],[Proveedor]]="","⚠ Falta el nombre",IF(COUNTIF(tblProveedores[Proveedor],tblProveedores[[#This Row],[Proveedor]])>1,"✖ Proveedor duplicado",IF(AND(tblProveedores[[#This Row],[Correo]]<>"",ISERROR(FIND("@",tblProveedores[[#This Row],[Correo]]))),"⚠ Correo no válido","✔ OK"))))
H12: =IF(tblProveedores[[#This Row],[Proveedor]]="","",COUNTIF(tblProductos[Proveedor],tblProveedores[[#This Row],[Proveedor]])) | I12: =IF(tblProveedores[[#This Row],[Proveedor]]="","",SUMPRODUCT(COUNTIFS(tblStock[Proveedor],tblProveedores[[#This Row],[Proveedor]],tblStock[Estado],{"INCONSISTENTE","AGOTADO","CRÍTICO","BAJO"}))) | J12: =IF(AND(tblProveedores[[#This Row],[Proveedor]]="",tblProveedores[[#This Row],[NIT]]="",tblProveedores[[#This Row],[Contacto]]="",tblProveedores[[#This Row],[Correo]]=""),"",IF(tblProveedores[[#This Row],[Proveedor]]="","⚠ Falta el nombre",IF(COUNTIF(tblProveedores[Proveedor],tblProveedores[[#This Row],[Proveedor]])>1,"✖ Proveedor duplicado",IF(AND(tblProveedores[[#This Row],[Correo]]<>"",ISERROR(FIND("@",tblProveedores[[#This Row],[Correo]]))),"⚠ Correo no válido","✔ OK"))))
H13: =IF(tblProveedores[[#This Row],[Proveedor]]="","",COUNTIF(tblProductos[Proveedor],tblProveedores[[#This Row],[Proveedor]])) | I13: =IF(tblProveedores[[#This Row],[Proveedor]]="","",SUMPRODUCT(COUNTIFS(tblStock[Proveedor],tblProveedores[[#This Row],[Proveedor]],tblStock[Estado],{"INCONSISTENTE","AGOTADO","CRÍTICO","BAJO"}))) | J13: =IF(AND(tblProveedores[[#This Row],[Proveedor]]="",tblProveedores[[#This Row],[NIT]]="",tblProveedores[[#This Row],[Contacto]]="",tblProveedores[[#This Row],[Correo]]=""),"",IF(tblProveedores[[#This Row],[Proveedor]]="","⚠ Falta el nombre",IF(COUNTIF(tblProveedores[Proveedor],tblProveedores[[#This Row],[Proveedor]])>1,"✖ Proveedor duplicado",IF(AND(tblProveedores[[#This Row],[Correo]]<>"",ISERROR(FIND("@",tblProveedores[[#This Row],[Correo]]))),"⚠ Correo no válido","✔ OK"))))
H14: =IF(tblProveedores[[#This Row],[Proveedor]]="","",COUNTIF(tblProductos[Proveedor],tblProveedores[[#This Row],[Proveedor]])) | I14: =IF(tblProveedores[[#This Row],[Proveedor]]="","",SUMPRODUCT(COUNTIFS(tblStock[Proveedor],tblProveedores[[#This Row],[Proveedor]],tblStock[Estado],{"INCONSISTENTE","AGOTADO","CRÍTICO","BAJO"}))) | J14: =IF(AND(tblProveedores[[#This Row],[Proveedor]]="",tblProveedores[[#This Row],[NIT]]="",tblProveedores[[#This Row],[Contacto]]="",tblProveedores[[#This Row],[Correo]]=""),"",IF(tblProveedores[[#This Row],[Proveedor]]="","⚠ Falta el nombre",IF(COUNTIF(tblProveedores[Proveedor],tblProveedores[[#This Row],[Proveedor]])>1,"✖ Proveedor duplicado",IF(AND(tblProveedores[[#This Row],[Correo]]<>"",ISERROR(FIND("@",tblProveedores[[#This Row],[Correo]]))),"⚠ Correo no válido","✔ OK"))))
H15: =IF(tblProveedores[[#This Row],[Proveedor]]="","",COUNTIF(tblProductos[Proveedor],tblProveedores[[#This Row],[Proveedor]])) | I15: =IF(tblProveedores[[#This Row],[Proveedor]]="","",SUMPRODUCT(COUNTIFS(tblStock[Proveedor],tblProveedores[[#This Row],[Proveedor]],tblStock[Estado],{"INCONSISTENTE","AGOTADO","CRÍTICO","BAJO"}))) | J15: =IF(AND(tblProveedores[[#This Row],[Proveedor]]="",tblProveedores[[#This Row],[NIT]]="",tblProveedores[[#This Row],[Contacto]]="",tblProveedores[[#This Row],[Correo]]=""),"",IF(tblProveedores[[#This Row],[Proveedor]]="","⚠ Falta el nombre",IF(COUNTIF(tblProveedores[Proveedor],tblProveedores[[#This Row],[Proveedor]])>1,"✖ Proveedor duplicado",IF(AND(tblProveedores[[#This Row],[Correo]]<>"",ISERROR(FIND("@",tblProveedores[[#This Row],[Correo]]))),"⚠ Correo no válido","✔ OK"))))
H16: =IF(tblProveedores[[#This Row],[Proveedor]]="","",COUNTIF(tblProductos[Proveedor],tblProveedores[[#This Row],[Proveedor]])) | I16: =IF(tblProveedores[[#This Row],[Proveedor]]="","",SUMPRODUCT(COUNTIFS(tblStock[Proveedor],tblProveedores[[#This Row],[Proveedor]],tblStock[Estado],{"INCONSISTENTE","AGOTADO","CRÍTICO","BAJO"}))) | J16: =IF(AND(tblProveedores[[#This Row],[Proveedor]]="",tblProveedores[[#This Row],[NIT]]="",tblProveedores[[#This Row],[Contacto]]="",tblProveedores[[#This Row],[Correo]]=""),"",IF(tblProveedores[[#This Row],[Proveedor]]="","⚠ Falta el nombre",IF(COUNTIF(tblProveedores[Proveedor],tblProveedores[[#This Row],[Proveedor]])>1,"✖ Proveedor duplicado",IF(AND(tblProveedores[[#This Row],[Correo]]<>"",ISERROR(FIND("@",tblProveedores[[#This Row],[Correo]]))),"⚠ Correo no válido","✔ OK"))))
H17: =IF(tblProveedores[[#This Row],[Proveedor]]="","",COUNTIF(tblProductos[Proveedor],tblProveedores[[#This Row],[Proveedor]])) | I17: =IF(tblProveedores[[#This Row],[Proveedor]]="","",SUMPRODUCT(COUNTIFS(tblStock[Proveedor],tblProveedores[[#This Row],[Proveedor]],tblStock[Estado],{"INCONSISTENTE","AGOTADO","CRÍTICO","BAJO"}))) | J17: =IF(AND(tblProveedores[[#This Row],[Proveedor]]="",tblProveedores[[#This Row],[NIT]]="",tblProveedores[[#This Row],[Contacto]]="",tblProveedores[[#This Row],[Correo]]=""),"",IF(tblProveedores[[#This Row],[Proveedor]]="","⚠ Falta el nombre",IF(COUNTIF(tblProveedores[Proveedor],tblProveedores[[#This Row],[Proveedor]])>1,"✖ Proveedor duplicado",IF(AND(tblProveedores[[#This Row],[Correo]]<>"",ISERROR(FIND("@",tblProveedores[[#This Row],[Correo]]))),"⚠ Correo no válido","✔ OK"))))
H18: =IF(tblProveedores[[#This Row],[Proveedor]]="","",COUNTIF(tblProductos[Proveedor],tblProveedores[[#This Row],[Proveedor]])) | I18: =IF(tblProveedores[[#This Row],[Proveedor]]="","",SUMPRODUCT(COUNTIFS(tblStock[Proveedor],tblProveedores[[#This Row],[Proveedor]],tblStock[Estado],{"INCONSISTENTE","AGOTADO","CRÍTICO","BAJO"}))) | J18: =IF(AND(tblProveedores[[#This Row],[Proveedor]]="",tblProveedores[[#This Row],[NIT]]="",tblProveedores[[#This Row],[Contacto]]="",tblProveedores[[#This Row],[Correo]]=""),"",IF(tblProveedores[[#This Row],[Proveedor]]="","⚠ Falta el nombre",IF(COUNTIF(tblProveedores[Proveedor],tblProveedores[[#This Row],[Proveedor]])>1,"✖ Proveedor duplicado",IF(AND(tblProveedores[[#This Row],[Correo]]<>"",ISERROR(FIND("@",tblProveedores[[#This Row],[Correo]]))),"⚠ Correo no válido","✔ OK"))))
H19: =IF(tblProveedores[[#This Row],[Proveedor]]="","",COUNTIF(tblProductos[Proveedor],tblProveedores[[#This Row],[Proveedor]])) | I19: =IF(tblProveedores[[#This Row],[Proveedor]]="","",SUMPRODUCT(COUNTIFS(tblStock[Proveedor],tblProveedores[[#This Row],[Proveedor]],tblStock[Estado],{"INCONSISTENTE","AGOTADO","CRÍTICO","BAJO"}))) | J19: =IF(AND(tblProveedores[[#This Row],[Proveedor]]="",tblProveedores[[#This Row],[NIT]]="",tblProveedores[[#This Row],[Contacto]]="",tblProveedores[[#This Row],[Correo]]=""),"",IF(tblProveedores[[#This Row],[Proveedor]]="","⚠ Falta el nombre",IF(COUNTIF(tblProveedores[Proveedor],tblProveedores[[#This Row],[Proveedor]])>1,"✖ Proveedor duplicado",IF(AND(tblProveedores[[#This Row],[Correo]]<>"",ISERROR(FIND("@",tblProveedores[[#This Row],[Correo]]))),"⚠ Correo no válido","✔ OK"))))
... H107: =IF(tblProveedores[[#This Row],[Proveedor]]="","",COUNTIF(tblProductos[Proveedor],tblProveedores[[#This Row],[Proveedor]])) | I107: =IF(tblProveedores[[#This Row],[Proveedor]]="","",SUMPRODUCT(COUNTIFS(tblStock[Proveedor],tblProveedores[[#This Row],[Proveedor]],tblStock[Estado],{"INCONSISTENTE","AGOTADO","CRÍTICO","BAJO"}))) | J107: =IF(AND(tblProveedores[[#This Row],[Proveedor]]="",tblProveedores[[#This Row],[NIT]]="",tblProveedores[[#This Row],[Contacto]]="",tblProveedores[[#This Row],[Correo]]=""),"",IF(tblProveedores[[#This Row],[Proveedor]]="","⚠ Falta el nombre",IF(COUNTIF(tblProveedores[Proveedor],tblProveedores[[#This Row],[Proveedor]])>1,"✖ Proveedor duplicado",IF(AND(tblProveedores[[#This Row],[Correo]]<>"",ISERROR(FIND("@",tblProveedores[[#This Row],[Correo]]))),"⚠ Correo no válido","✔ OK"))))

Sheet 05_PRODUCTOS
B2: Catálogo de productos
B3: Datos maestros · Cada producto se registra una sola vez · Nunca borre filas (use Activo = NO)
B6: ✎ | C6: ✎ | D6: ✎ | E6: ✎ | F6: ✎ | G6: ✎ | H6: ✎ | I6: ✎ | J6: ✎ | K6: ✎ | L6: ƒx | M6: ƒx | N6: ƒx
B7: SKU | C7: Producto | D7: Categoría | E7: Unidad | F7: StockMin | G7: StockMax | H7: CostoUnitario | I7: Proveedor | J7: Ubicación | K7: Activo | L7: Etiqueta | M7: Movimientos | N7: Validación
L8: =IF(OR(tblProductos[[#This Row],[SKU]]="",tblProductos[[#This Row],[Producto]]=""),"",tblProductos[[#This Row],[SKU]]&" · "&tblProductos[[#This Row],[Producto]]) | M8: =IF(tblProductos[[#This Row],[SKU]]="","",COUNTIF(tblMovimientos[SKU],tblProductos[[#This Row],[SKU]])) | N8: =IF(AND(tblProductos[[#This Row],[SKU]]="",tblProductos[[#This Row],[Producto]]=""),"",IF(OR(tblProductos[[#This Row],[SKU]]="",tblProductos[[#This Row],[Producto]]="",tblProductos[[#This Row],[Categoría]]="",tblProductos[[#This Row],[Unidad]]=""),"⚠ Faltan datos",IF(COUNTIF(tblProductos[SKU],tblProductos[[#This Row],[SKU]])>1,"✖ SKU duplicado",IF(ISNUMBER(FIND(" ",tblProductos[[#This Row],[SKU]])),"✖ SKU con espacios",IF(ISNA(MATCH(tblProductos[[#This Row],[Categoría]],lstCategorias,0)),"✖ Categoría no existe",IF(ISNA(MATCH(tblProductos[[#This Row],[Unidad]],lstUniCod,0)),"✖ Unidad no existe",IF(AND(tblProductos[[#This Row],[Proveedor]]<>"",ISNA(MATCH(tblProductos[[#This Row],[Proveedor]],tblProveedores[Proveedor],0))),"✖ Proveedor no existe",IF(AND(N(tblProductos[[#This Row],[StockMax]])>0,N(tblProductos[[#This Row],[StockMin]])>N(tblProductos[[#This Row],[StockMax]])),"⚠ Mínimo mayor que máximo",IF(tblProductos[[#This Row],[Activo]]="NO","● Inactivo","✔ OK")))))))))
L9: =IF(OR(tblProductos[[#This Row],[SKU]]="",tblProductos[[#This Row],[Producto]]=""),"",tblProductos[[#This Row],[SKU]]&" · "&tblProductos[[#This Row],[Producto]]) | M9: =IF(tblProductos[[#This Row],[SKU]]="","",COUNTIF(tblMovimientos[SKU],tblProductos[[#This Row],[SKU]])) | N9: =IF(AND(tblProductos[[#This Row],[SKU]]="",tblProductos[[#This Row],[Producto]]=""),"",IF(OR(tblProductos[[#This Row],[SKU]]="",tblProductos[[#This Row],[Producto]]="",tblProductos[[#This Row],[Categoría]]="",tblProductos[[#This Row],[Unidad]]=""),"⚠ Faltan datos",IF(COUNTIF(tblProductos[SKU],tblProductos[[#This Row],[SKU]])>1,"✖ SKU duplicado",IF(ISNUMBER(FIND(" ",tblProductos[[#This Row],[SKU]])),"✖ SKU con espacios",IF(ISNA(MATCH(tblProductos[[#This Row],[Categoría]],lstCategorias,0)),"✖ Categoría no existe",IF(ISNA(MATCH(tblProductos[[#This Row],[Unidad]],lstUniCod,0)),"✖ Unidad no existe",IF(AND(tblProductos[[#This Row],[Proveedor]]<>"",ISNA(MATCH(tblProductos[[#This Row],[Proveedor]],tblProveedores[Proveedor],0))),"✖ Proveedor no existe",IF(AND(N(tblProductos[[#This Row],[StockMax]])>0,N(tblProductos[[#This Row],[StockMin]])>N(tblProductos[[#This Row],[StockMax]])),"⚠ Mínimo mayor que máximo",IF(tblProductos[[#This Row],[Activo]]="NO","● Inactivo","✔ OK")))))))))
L10: =IF(OR(tblProductos[[#This Row],[SKU]]="",tblProductos[[#This Row],[Producto]]=""),"",tblProductos[[#This Row],[SKU]]&" · "&tblProductos[[#This Row],[Producto]]) | M10: =IF(tblProductos[[#This Row],[SKU]]="","",COUNTIF(tblMovimientos[SKU],tblProductos[[#This Row],[SKU]])) | N10: =IF(AND(tblProductos[[#This Row],[SKU]]="",tblProductos[[#This Row],[Producto]]=""),"",IF(OR(tblProductos[[#This Row],[SKU]]="",tblProductos[[#This Row],[Producto]]="",tblProductos[[#This Row],[Categoría]]="",tblProductos[[#This Row],[Unidad]]=""),"⚠ Faltan datos",IF(COUNTIF(tblProductos[SKU],tblProductos[[#This Row],[SKU]])>1,"✖ SKU duplicado",IF(ISNUMBER(FIND(" ",tblProductos[[#This Row],[SKU]])),"✖ SKU con espacios",IF(ISNA(MATCH(tblProductos[[#This Row],[Categoría]],lstCategorias,0)),"✖ Categoría no existe",IF(ISNA(MATCH(tblProductos[[#This Row],[Unidad]],lstUniCod,0)),"✖ Unidad no existe",IF(AND(tblProductos[[#This Row],[Proveedor]]<>"",ISNA(MATCH(tblProductos[[#This Row],[Proveedor]],tblProveedores[Proveedor],0))),"✖ Proveedor no existe",IF(AND(N(tblProductos[[#This Row],[StockMax]])>0,N(tblProductos[[#This Row],[StockMin]])>N(tblProductos[[#This Row],[StockMax]])),"⚠ Mínimo mayor que máximo",IF(tblProductos[[#This Row],[Activo]]="NO","● Inactivo","✔ OK")))))))))
L11: =IF(OR(tblProductos[[#This Row],[SKU]]="",tblProductos[[#This Row],[Producto]]=""),"",tblProductos[[#This Row],[SKU]]&" · "&tblProductos[[#This Row],[Producto]]) | M11: =IF(tblProductos[[#This Row],[SKU]]="","",COUNTIF(tblMovimientos[SKU],tblProductos[[#This Row],[SKU]])) | N11: =IF(AND(tblProductos[[#This Row],[SKU]]="",tblProductos[[#This Row],[Producto]]=""),"",IF(OR(tblProductos[[#This Row],[SKU]]="",tblProductos[[#This Row],[Producto]]="",tblProductos[[#This Row],[Categoría]]="",tblProductos[[#This Row],[Unidad]]=""),"⚠ Faltan datos",IF(COUNTIF(tblProductos[SKU],tblProductos[[#This Row],[SKU]])>1,"✖ SKU duplicado",IF(ISNUMBER(FIND(" ",tblProductos[[#This Row],[SKU]])),"✖ SKU con espacios",IF(ISNA(MATCH(tblProductos[[#This Row],[Categoría]],lstCategorias,0)),"✖ Categoría no existe",IF(ISNA(MATCH(tblProductos[[#This Row],[Unidad]],lstUniCod,0)),"✖ Unidad no existe",IF(AND(tblProductos[[#This Row],[Proveedor]]<>"",ISNA(MATCH(tblProductos[[#This Row],[Proveedor]],tblProveedores[Proveedor],0))),"✖ Proveedor no existe",IF(AND(N(tblProductos[[#This Row],[StockMax]])>0,N(tblProductos[[#This Row],[StockMin]])>N(tblProductos[[#This Row],[StockMax]])),"⚠ Mínimo mayor que máximo",IF(tblProductos[[#This Row],[Activo]]="NO","● Inactivo","✔ OK")))))))))
L12: =IF(OR(tblProductos[[#This Row],[SKU]]="",tblProductos[[#This Row],[Producto]]=""),"",tblProductos[[#This Row],[SKU]]&" · "&tblProductos[[#This Row],[Producto]]) | M12: =IF(tblProductos[[#This Row],[SKU]]="","",COUNTIF(tblMovimientos[SKU],tblProductos[[#This Row],[SKU]])) | N12: =IF(AND(tblProductos[[#This Row],[SKU]]="",tblProductos[[#This Row],[Producto]]=""),"",IF(OR(tblProductos[[#This Row],[SKU]]="",tblProductos[[#This Row],[Producto]]="",tblProductos[[#This Row],[Categoría]]="",tblProductos[[#This Row],[Unidad]]=""),"⚠ Faltan datos",IF(COUNTIF(tblProductos[SKU],tblProductos[[#This Row],[SKU]])>1,"✖ SKU duplicado",IF(ISNUMBER(FIND(" ",tblProductos[[#This Row],[SKU]])),"✖ SKU con espacios",IF(ISNA(MATCH(tblProductos[[#This Row],[Categoría]],lstCategorias,0)),"✖ Categoría no existe",IF(ISNA(MATCH(tblProductos[[#This Row],[Unidad]],lstUniCod,0)),"✖ Unidad no existe",IF(AND(tblProductos[[#This Row],[Proveedor]]<>"",ISNA(MATCH(tblProductos[[#This Row],[Proveedor]],tblProveedores[Proveedor],0))),"✖ Proveedor no existe",IF(AND(N(tblProductos[[#This Row],[StockMax]])>0,N(tblProductos[[#This Row],[StockMin]])>N(tblProductos[[#This Row],[StockMax]])),"⚠ Mínimo mayor que máximo",IF(tblProductos[[#This Row],[Activo]]="NO","● Inactivo","✔ OK")))))))))
L13: =IF(OR(tblProductos[[#This Row],[SKU]]="",tblProductos[[#This Row],[Producto]]=""),"",tblProductos[[#This Row],[SKU]]&" · "&tblProductos[[#This Row],[Producto]]) | M13: =IF(tblProductos[[#This Row],[SKU]]="","",COUNTIF(tblMovimientos[SKU],tblProductos[[#This Row],[SKU]])) | N13: =IF(AND(tblProductos[[#This Row],[SKU]]="",tblProductos[[#This Row],[Producto]]=""),"",IF(OR(tblProductos[[#This Row],[SKU]]="",tblProductos[[#This Row],[Producto]]="",tblProductos[[#This Row],[Categoría]]="",tblProductos[[#This Row],[Unidad]]=""),"⚠ Faltan datos",IF(COUNTIF(tblProductos[SKU],tblProductos[[#This Row],[SKU]])>1,"✖ SKU duplicado",IF(ISNUMBER(FIND(" ",tblProductos[[#This Row],[SKU]])),"✖ SKU con espacios",IF(ISNA(MATCH(tblProductos[[#This Row],[Categoría]],lstCategorias,0)),"✖ Categoría no existe",IF(ISNA(MATCH(tblProductos[[#This Row],[Unidad]],lstUniCod,0)),"✖ Unidad no existe",IF(AND(tblProductos[[#This Row],[Proveedor]]<>"",ISNA(MATCH(tblProductos[[#This Row],[Proveedor]],tblProveedores[Proveedor],0))),"✖ Proveedor no existe",IF(AND(N(tblProductos[[#This Row],[StockMax]])>0,N(tblProductos[[#This Row],[StockMin]])>N(tblProductos[[#This Row],[StockMax]])),"⚠ Mínimo mayor que máximo",IF(tblProductos[[#This Row],[Activo]]="NO","● Inactivo","✔ OK")))))))))
L14: =IF(OR(tblProductos[[#This Row],[SKU]]="",tblProductos[[#This Row],[Producto]]=""),"",tblProductos[[#This Row],[SKU]]&" · "&tblProductos[[#This Row],[Producto]]) | M14: =IF(tblProductos[[#This Row],[SKU]]="","",COUNTIF(tblMovimientos[SKU],tblProductos[[#This Row],[SKU]])) | N14: =IF(AND(tblProductos[[#This Row],[SKU]]="",tblProductos[[#This Row],[Producto]]=""),"",IF(OR(tblProductos[[#This Row],[SKU]]="",tblProductos[[#This Row],[Producto]]="",tblProductos[[#This Row],[Categoría]]="",tblProductos[[#This Row],[Unidad]]=""),"⚠ Faltan datos",IF(COUNTIF(tblProductos[SKU],tblProductos[[#This Row],[SKU]])>1,"✖ SKU duplicado",IF(ISNUMBER(FIND(" ",tblProductos[[#This Row],[SKU]])),"✖ SKU con espacios",IF(ISNA(MATCH(tblProductos[[#This Row],[Categoría]],lstCategorias,0)),"✖ Categoría no existe",IF(ISNA(MATCH(tblProductos[[#This Row],[Unidad]],lstUniCod,0)),"✖ Unidad no existe",IF(AND(tblProductos[[#This Row],[Proveedor]]<>"",ISNA(MATCH(tblProductos[[#This Row],[Proveedor]],tblProveedores[Proveedor],0))),"✖ Proveedor no existe",IF(AND(N(tblProductos[[#This Row],[StockMax]])>0,N(tblProductos[[#This Row],[StockMin]])>N(tblProductos[[#This Row],[StockMax]])),"⚠ Mínimo mayor que máximo",IF(tblProductos[[#This Row],[Activo]]="NO","● Inactivo","✔ OK")))))))))
L15: =IF(OR(tblProductos[[#This Row],[SKU]]="",tblProductos[[#This Row],[Producto]]=""),"",tblProductos[[#This Row],[SKU]]&" · "&tblProductos[[#This Row],[Producto]]) | M15: =IF(tblProductos[[#This Row],[SKU]]="","",COUNTIF(tblMovimientos[SKU],tblProductos[[#This Row],[SKU]])) | N15: =IF(AND(tblProductos[[#This Row],[SKU]]="",tblProductos[[#This Row],[Producto]]=""),"",IF(OR(tblProductos[[#This Row],[SKU]]="",tblProductos[[#This Row],[Producto]]="",tblProductos[[#This Row],[Categoría]]="",tblProductos[[#This Row],[Unidad]]=""),"⚠ Faltan datos",IF(COUNTIF(tblProductos[SKU],tblProductos[[#This Row],[SKU]])>1,"✖ SKU duplicado",IF(ISNUMBER(FIND(" ",tblProductos[[#This Row],[SKU]])),"✖ SKU con espacios",IF(ISNA(MATCH(tblProductos[[#This Row],[Categoría]],lstCategorias,0)),"✖ Categoría no existe",IF(ISNA(MATCH(tblProductos[[#This Row],[Unidad]],lstUniCod,0)),"✖ Unidad no existe",IF(AND(tblProductos[[#This Row],[Proveedor]]<>"",ISNA(MATCH(tblProductos[[#This Row],[Proveedor]],tblProveedores[Proveedor],0))),"✖ Proveedor no existe",IF(AND(N(tblProductos[[#This Row],[StockMax]])>0,N(tblProductos[[#This Row],[StockMin]])>N(tblProductos[[#This Row],[StockMax]])),"⚠ Mínimo mayor que máximo",IF(tblProductos[[#This Row],[Activo]]="NO","● Inactivo","✔ OK")))))))))
L16: =IF(OR(tblProductos[[#This Row],[SKU]]="",tblProductos[[#This Row],[Producto]]=""),"",tblProductos[[#This Row],[SKU]]&" · "&tblProductos[[#This Row],[Producto]]) | M16: =IF(tblProductos[[#This Row],[SKU]]="","",COUNTIF(tblMovimientos[SKU],tblProductos[[#This Row],[SKU]])) | N16: =IF(AND(tblProductos[[#This Row],[SKU]]="",tblProductos[[#This Row],[Producto]]=""),"",IF(OR(tblProductos[[#This Row],[SKU]]="",tblProductos[[#This Row],[Producto]]="",tblProductos[[#This Row],[Categoría]]="",tblProductos[[#This Row],[Unidad]]=""),"⚠ Faltan datos",IF(COUNTIF(tblProductos[SKU],tblProductos[[#This Row],[SKU]])>1,"✖ SKU duplicado",IF(ISNUMBER(FIND(" ",tblProductos[[#This Row],[SKU]])),"✖ SKU con espacios",IF(ISNA(MATCH(tblProductos[[#This Row],[Categoría]],lstCategorias,0)),"✖ Categoría no existe",IF(ISNA(MATCH(tblProductos[[#This Row],[Unidad]],lstUniCod,0)),"✖ Unidad no existe",IF(AND(tblProductos[[#This Row],[Proveedor]]<>"",ISNA(MATCH(tblProductos[[#This Row],[Proveedor]],tblProveedores[Proveedor],0))),"✖ Proveedor no existe",IF(AND(N(tblProductos[[#This Row],[StockMax]])>0,N(tblProductos[[#This Row],[StockMin]])>N(tblProductos[[#This Row],[StockMax]])),"⚠ Mínimo mayor que máximo",IF(tblProductos[[#This Row],[Activo]]="NO","● Inactivo","✔ OK")))))))))
L17: =IF(OR(tblProductos[[#This Row],[SKU]]="",tblProductos[[#This Row],[Producto]]=""),"",tblProductos[[#This Row],[SKU]]&" · "&tblProductos[[#This Row],[Producto]]) | M17: =IF(tblProductos[[#This Row],[SKU]]="","",COUNTIF(tblMovimientos[SKU],tblProductos[[#This Row],[SKU]])) | N17: =IF(AND(tblProductos[[#This Row],[SKU]]="",tblProductos[[#This Row],[Producto]]=""),"",IF(OR(tblProductos[[#This Row],[SKU]]="",tblProductos[[#This Row],[Producto]]="",tblProductos[[#This Row],[Categoría]]="",tblProductos[[#This Row],[Unidad]]=""),"⚠ Faltan datos",IF(COUNTIF(tblProductos[SKU],tblProductos[[#This Row],[SKU]])>1,"✖ SKU duplicado",IF(ISNUMBER(FIND(" ",tblProductos[[#This Row],[SKU]])),"✖ SKU con espacios",IF(ISNA(MATCH(tblProductos[[#This Row],[Categoría]],lstCategorias,0)),"✖ Categoría no existe",IF(ISNA(MATCH(tblProductos[[#This Row],[Unidad]],lstUniCod,0)),"✖ Unidad no existe",IF(AND(tblProductos[[#This Row],[Proveedor]]<>"",ISNA(MATCH(tblProductos[[#This Row],[Proveedor]],tblProveedores[Proveedor],0))),"✖ Proveedor no existe",IF(AND(N(tblProductos[[#This Row],[StockMax]])>0,N(tblProductos[[#This Row],[StockMin]])>N(tblProductos[[#This Row],[StockMax]])),"⚠ Mínimo mayor que máximo",IF(tblProductos[[#This Row],[Activo]]="NO","● Inactivo","✔ OK")))))))))
L18: =IF(OR(tblProductos[[#This Row],[SKU]]="",tblProductos[[#This Row],[Producto]]=""),"",tblProductos[[#This Row],[SKU]]&" · "&tblProductos[[#This Row],[Producto]]) | M18: =IF(tblProductos[[#This Row],[SKU]]="","",COUNTIF(tblMovimientos[SKU],tblProductos[[#This Row],[SKU]])) | N18: =IF(AND(tblProductos[[#This Row],[SKU]]="",tblProductos[[#This Row],[Producto]]=""),"",IF(OR(tblProductos[[#This Row],[SKU]]="",tblProductos[[#This Row],[Producto]]="",tblProductos[[#This Row],[Categoría]]="",tblProductos[[#This Row],[Unidad]]=""),"⚠ Faltan datos",IF(COUNTIF(tblProductos[SKU],tblProductos[[#This Row],[SKU]])>1,"✖ SKU duplicado",IF(ISNUMBER(FIND(" ",tblProductos[[#This Row],[SKU]])),"✖ SKU con espacios",IF(ISNA(MATCH(tblProductos[[#This Row],[Categoría]],lstCategorias,0)),"✖ Categoría no existe",IF(ISNA(MATCH(tblProductos[[#This Row],[Unidad]],lstUniCod,0)),"✖ Unidad no existe",IF(AND(tblProductos[[#This Row],[Proveedor]]<>"",ISNA(MATCH(tblProductos[[#This Row],[Proveedor]],tblProveedores[Proveedor],0))),"✖ Proveedor no existe",IF(AND(N(tblProductos[[#This Row],[StockMax]])>0,N(tblProductos[[#This Row],[StockMin]])>N(tblProductos[[#This Row],[StockMax]])),"⚠ Mínimo mayor que máximo",IF(tblProductos[[#This Row],[Activo]]="NO","● Inactivo","✔ OK")))))))))
L19: =IF(OR(tblProductos[[#This Row],[SKU]]="",tblProductos[[#This Row],[Producto]]=""),"",tblProductos[[#This Row],[SKU]]&" · "&tblProductos[[#This Row],[Producto]]) | M19: =IF(tblProductos[[#This Row],[SKU]]="","",COUNTIF(tblMovimientos[SKU],tblProductos[[#This Row],[SKU]])) | N19: =IF(AND(tblProductos[[#This Row],[SKU]]="",tblProductos[[#This Row],[Producto]]=""),"",IF(OR(tblProductos[[#This Row],[SKU]]="",tblProductos[[#This Row],[Producto]]="",tblProductos[[#This Row],[Categoría]]="",tblProductos[[#This Row],[Unidad]]=""),"⚠ Faltan datos",IF(COUNTIF(tblProductos[SKU],tblProductos[[#This Row],[SKU]])>1,"✖ SKU duplicado",IF(ISNUMBER(FIND(" ",tblProductos[[#This Row],[SKU]])),"✖ SKU con espacios",IF(ISNA(MATCH(tblProductos[[#This Row],[Categoría]],lstCategorias,0)),"✖ Categoría no existe",IF(ISNA(MATCH(tblProductos[[#This Row],[Unidad]],lstUniCod,0)),"✖ Unidad no existe",IF(AND(tblProductos[[#This Row],[Proveedor]]<>"",ISNA(MATCH(tblProductos[[#This Row],[Proveedor]],tblProveedores[Proveedor],0))),"✖ Proveedor no existe",IF(AND(N(tblProductos[[#This Row],[StockMax]])>0,N(tblProductos[[#This Row],[StockMin]])>N(tblProductos[[#This Row],[StockMax]])),"⚠ Mínimo mayor que máximo",IF(tblProductos[[#This Row],[Activo]]="NO","● Inactivo","✔ OK")))))))))
... L507: =IF(OR(tblProductos[[#This Row],[SKU]]="",tblProductos[[#This Row],[Producto]]=""),"",tblProductos[[#This Row],[SKU]]&" · "&tblProductos[[#This Row],[Producto]]) | M507: =IF(tblProductos[[#This Row],[SKU]]="","",COUNTIF(tblMovimientos[SKU],tblProductos[[#This Row],[SKU]])) | N507: =IF(AND(tblProductos[[#This Row],[SKU]]="",tblProductos[[#This Row],[Producto]]=""),"",IF(OR(tblProductos[[#This Row],[SKU]]="",tblProductos[[#This Row],[Producto]]="",tblProductos[[#This Row],[Categoría]]="",tblProductos[[#This Row],[Unidad]]=""),"⚠ Faltan datos",IF(COUNTIF(tblProductos[SKU],tblProductos[[#This Row],[SKU]])>1,"✖ SKU duplicado",IF(ISNUMBER(FIND(" ",tblProductos[[#This Row],[SKU]])),"✖ SKU con espacios",IF(ISNA(MATCH(tblProductos[[#This Row],[Categoría]],lstCategorias,0)),"✖ Categoría no existe",IF(ISNA(MATCH(tblProductos[[#This Row],[Unidad]],lstUniCod,0)),"✖ Unidad no existe",IF(AND(tblProductos[[#This Row],[Proveedor]]<>"",ISNA(MATCH(tblProductos[[#This Row],[Proveedor]],tblProveedores[Proveedor],0))),"✖ Proveedor no existe",IF(AND(N(tblProductos[[#This Row],[StockMax]])>0,N(tblProductos[[#This Row],[StockMin]])>N(tblProductos[[#This Row],[StockMax]])),"⚠ Mínimo mayor que máximo",IF(tblProductos[[#This Row],[Activo]]="NO","● Inactivo","✔ OK")))))))))

Sheet 06_UNIDADES
B2: Unidades de medida
B3: Capa de configuración (oculta) · Define si la cantidad admite decimales
B7: Código | C7: Unidad | D7: Decimales | E7: Descripción
B8: UND | C8: Unidad | D8: NO | E8: Pieza individual
B9: CAJA | C9: Caja | D9: NO | E9: Caja cerrada del proveedor
B10: PAQ | C10: Paquete | D10: NO | E10: Paquete o bolsa cerrada
B11: PAR | C11: Par | D11: NO | E11: Par (guantes, botas)
B12: ROLLO | C12: Rollo | D12: NO | E12: Rollo completo
B13: KG | C13: Kilogramo | D13: SI | E13: Peso en kilogramos
B14: GL | C14: Galón | D14: SI | E14: Volumen en galones
B15: LT | C15: Litro | D15: SI | E15: Volumen en litros
B16: MT | C16: Metro | D16: SI | E16: Longitud en metros

Sheet 10_MOVIMIENTOS
B2: Bitácora de movimientos
B3: Capa de escritura · Registro inmutable (append-only) de entradas, salidas y ajustes
B6: ƒx | C6: ✎ | D6: ✎ | E6: ✎ | F6: ✎ | G6: ƒx | H6: ƒx | I6: ✎ | J6: ƒx | K6: ƒx | L6: ƒx | M6: ƒx | N6: ✎ | O6: ✎ | P6: ✎
B7: ID | C7: Fecha | D7: Tipo | E7: Categoría | F7: Producto | G7: SKU | H7: Unidad | I7: Cantidad | J7: FactorStock | K7: CantidadNeta | L7: Saldo | M7: Estado | N7: Documento | O7: Responsable | P7: Observaciones
B8: =IF((tblMovimientos[[#This Row],[Fecha]]&tblMovimientos[[#This Row],[Tipo]]&tblMovimientos[[#This Row],[Producto]]&tblMovimientos[[#This Row],[Cantidad]])="","",ROW()-ROW(tblMovimientos[#Headers])) | G8: =IF(tblMovimientos[[#This Row],[Producto]]="","",TRIM(LEFT(tblMovimientos[[#This Row],[Producto]],FIND(" · ",tblMovimientos[[#This Row],[Producto]]&" · ")-1))) | H8: =IF(tblMovimientos[[#This Row],[SKU]]="","",IFERROR(INDEX(tblProductos[Unidad],MATCH(tblMovimientos[[#This Row],[SKU]],tblProductos[SKU],0)),"?")) | J8: =IF(tblMovimientos[[#This Row],[Tipo]]="","",IFERROR(INDEX(tblTiposMov[FactorStock],MATCH(tblMovimientos[[#This Row],[Tipo]],tblTiposMov[Tipo],0)),0)) | K8: =IF(OR(tblMovimientos[[#This Row],[Cantidad]]="",tblMovimientos[[#This Row],[FactorStock]]=""),"",IF(ISNUMBER(tblMovimientos[[#This Row],[Cantidad]]),tblMovimientos[[#This Row],[Cantidad]]*tblMovimientos[[#This Row],[FactorStock]],"")) | L8: =IF(tblMovimientos[[#This Row],[CantidadNeta]]="","",SUMIFS(INDEX(tblMovimientos[CantidadNeta],1):tblMovimientos[[#This Row],[CantidadNeta]],INDEX(tblMovimientos[SKU],1):tblMovimientos[[#This Row],[SKU]],tblMovimientos[[#This Row],[SKU]])) | M8: =IF((tblMovimientos[[#This Row],[Fecha]]&tblMovimientos[[#This Row],[Tipo]]&tblMovimientos[[#This Row],[Producto]]&tblMovimientos[[#This Row],[Cantidad]])="","",IF(OR(tblMovimientos[[#This Row],[Fecha]]="",tblMovimientos[[#This Row],[Tipo]]="",tblMovimientos[[#This Row],[Producto]]="",tblMovimientos[[#This Row],[Cantidad]]="",tblMovimientos[[#This Row],[Responsable]]=""),"⚠ Incompleto",IF(tblMovimientos[[#This Row],[Unidad]]="?","✖ Producto no existe",IF(tblMovimientos[[#This Row],[FactorStock]]=0,"✖ Tipo no válido",IF(NOT(ISNUMBER(tblMovimientos[[#This Row],[Cantidad]])),"✖ Cantidad inválida",IF(tblMovimientos[[#This Row],[Cantidad]]<=0,"✖ Cantidad inválida",IF(AND(tblMovimientos[[#This Row],[Categoría]]<>"",tblMovimientos[[#This Row],[Categoría]]<>INDEX(tblProductos[Categoría],MATCH(tblMovimientos[[#This Row],[SKU]],tblProductos[SKU],0))),"⚠ Categoría no coincide",IF(tblMovimientos[[#This Row],[Saldo]]<0,"✖ Stock insuficiente",IF(AND(LEFT(tblMovimientos[[#This Row],[Tipo]],6)="AJUSTE",tblMovimientos[[#This Row],[Observaciones]]=""),"⚠ Justifique el ajuste","✔ Registrado")))))))))
B9: =IF((tblMovimientos[[#This Row],[Fecha]]&tblMovimientos[[#This Row],[Tipo]]&tblMovimientos[[#This Row],[Producto]]&tblMovimientos[[#This Row],[Cantidad]])="","",ROW()-ROW(tblMovimientos[#Headers])) | G9: =IF(tblMovimientos[[#This Row],[Producto]]="","",TRIM(LEFT(tblMovimientos[[#This Row],[Producto]],FIND(" · ",tblMovimientos[[#This Row],[Producto]]&" · ")-1))) | H9: =IF(tblMovimientos[[#This Row],[SKU]]="","",IFERROR(INDEX(tblProductos[Unidad],MATCH(tblMovimientos[[#This Row],[SKU]],tblProductos[SKU],0)),"?")) | J9: =IF(tblMovimientos[[#This Row],[Tipo]]="","",IFERROR(INDEX(tblTiposMov[FactorStock],MATCH(tblMovimientos[[#This Row],[Tipo]],tblTiposMov[Tipo],0)),0)) | K9: =IF(OR(tblMovimientos[[#This Row],[Cantidad]]="",tblMovimientos[[#This Row],[FactorStock]]=""),"",IF(ISNUMBER(tblMovimientos[[#This Row],[Cantidad]]),tblMovimientos[[#This Row],[Cantidad]]*tblMovimientos[[#This Row],[FactorStock]],"")) | L9: =IF(tblMovimientos[[#This Row],[CantidadNeta]]="","",SUMIFS(INDEX(tblMovimientos[CantidadNeta],1):tblMovimientos[[#This Row],[CantidadNeta]],INDEX(tblMovimientos[SKU],1):tblMovimientos[[#This Row],[SKU]],tblMovimientos[[#This Row],[SKU]])) | M9: =IF((tblMovimientos[[#This Row],[Fecha]]&tblMovimientos[[#This Row],[Tipo]]&tblMovimientos[[#This Row],[Producto]]&tblMovimientos[[#This Row],[Cantidad]])="","",IF(OR(tblMovimientos[[#This Row],[Fecha]]="",tblMovimientos[[#This Row],[Tipo]]="",tblMovimientos[[#This Row],[Producto]]="",tblMovimientos[[#This Row],[Cantidad]]="",tblMovimientos[[#This Row],[Responsable]]=""),"⚠ Incompleto",IF(tblMovimientos[[#This Row],[Unidad]]="?","✖ Producto no existe",IF(tblMovimientos[[#This Row],[FactorStock]]=0,"✖ Tipo no válido",IF(NOT(ISNUMBER(tblMovimientos[[#This Row],[Cantidad]])),"✖ Cantidad inválida",IF(tblMovimientos[[#This Row],[Cantidad]]<=0,"✖ Cantidad inválida",IF(AND(tblMovimientos[[#This Row],[Categoría]]<>"",tblMovimientos[[#This Row],[Categoría]]<>INDEX(tblProductos[Categoría],MATCH(tblMovimientos[[#This Row],[SKU]],tblProductos[SKU],0))),"⚠ Categoría no coincide",IF(tblMovimientos[[#This Row],[Saldo]]<0,"✖ Stock insuficiente",IF(AND(LEFT(tblMovimientos[[#This Row],[Tipo]],6)="AJUSTE",tblMovimientos[[#This Row],[Observaciones]]=""),"⚠ Justifique el ajuste","✔ Registrado")))))))))
B10: =IF((tblMovimientos[[#This Row],[Fecha]]&tblMovimientos[[#This Row],[Tipo]]&tblMovimientos[[#This Row],[Producto]]&tblMovimientos[[#This Row],[Cantidad]])="","",ROW()-ROW(tblMovimientos[#Headers])) | G10: =IF(tblMovimientos[[#This Row],[Producto]]="","",TRIM(LEFT(tblMovimientos[[#This Row],[Producto]],FIND(" · ",tblMovimientos[[#This Row],[Producto]]&" · ")-1))) | H10: =IF(tblMovimientos[[#This Row],[SKU]]="","",IFERROR(INDEX(tblProductos[Unidad],MATCH(tblMovimientos[[#This Row],[SKU]],tblProductos[SKU],0)),"?")) | J10: =IF(tblMovimientos[[#This Row],[Tipo]]="","",IFERROR(INDEX(tblTiposMov[FactorStock],MATCH(tblMovimientos[[#This Row],[Tipo]],tblTiposMov[Tipo],0)),0)) | K10: =IF(OR(tblMovimientos[[#This Row],[Cantidad]]="",tblMovimientos[[#This Row],[FactorStock]]=""),"",IF(ISNUMBER(tblMovimientos[[#This Row],[Cantidad]]),tblMovimientos[[#This Row],[Cantidad]]*tblMovimientos[[#This Row],[FactorStock]],"")) | L10: =IF(tblMovimientos[[#This Row],[CantidadNeta]]="","",SUMIFS(INDEX(tblMovimientos[CantidadNeta],1):tblMovimientos[[#This Row],[CantidadNeta]],INDEX(tblMovimientos[SKU],1):tblMovimientos[[#This Row],[SKU]],tblMovimientos[[#This Row],[SKU]])) | M10: =IF((tblMovimientos[[#This Row],[Fecha]]&tblMovimientos[[#This Row],[Tipo]]&tblMovimientos[[#This Row],[Producto]]&tblMovimientos[[#This Row],[Cantidad]])="","",IF(OR(tblMovimientos[[#This Row],[Fecha]]="",tblMovimientos[[#This Row],[Tipo]]="",tblMovimientos[[#This Row],[Producto]]="",tblMovimientos[[#This Row],[Cantidad]]="",tblMovimientos[[#This Row],[Responsable]]=""),"⚠ Incompleto",IF(tblMovimientos[[#This Row],[Unidad]]="?","✖ Producto no existe",IF(tblMovimientos[[#This Row],[FactorStock]]=0,"✖ Tipo no válido",IF(NOT(ISNUMBER(tblMovimientos[[#This Row],[Cantidad]])),"✖ Cantidad inválida",IF(tblMovimientos[[#This Row],[Cantidad]]<=0,"✖ Cantidad inválida",IF(AND(tblMovimientos[[#This Row],[Categoría]]<>"",tblMovimientos[[#This Row],[Categoría]]<>INDEX(tblProductos[Categoría],MATCH(tblMovimientos[[#This Row],[SKU]],tblProductos[SKU],0))),"⚠ Categoría no coincide",IF(tblMovimientos[[#This Row],[Saldo]]<0,"✖ Stock insuficiente",IF(AND(LEFT(tblMovimientos[[#This Row],[Tipo]],6)="AJUSTE",tblMovimientos[[#This Row],[Observaciones]]=""),"⚠ Justifique el ajuste","✔ Registrado")))))))))
B11: =IF((tblMovimientos[[#This Row],[Fecha]]&tblMovimientos[[#This Row],[Tipo]]&tblMovimientos[[#This Row],[Producto]]&tblMovimientos[[#This Row],[Cantidad]])="","",ROW()-ROW(tblMovimientos[#Headers])) | G11: =IF(tblMovimientos[[#This Row],[Producto]]="","",TRIM(LEFT(tblMovimientos[[#This Row],[Producto]],FIND(" · ",tblMovimientos[[#This Row],[Producto]]&" · ")-1))) | H11: =IF(tblMovimientos[[#This Row],[SKU]]="","",IFERROR(INDEX(tblProductos[Unidad],MATCH(tblMovimientos[[#This Row],[SKU]],tblProductos[SKU],0)),"?")) | J11: =IF(tblMovimientos[[#This Row],[Tipo]]="","",IFERROR(INDEX(tblTiposMov[FactorStock],MATCH(tblMovimientos[[#This Row],[Tipo]],tblTiposMov[Tipo],0)),0)) | K11: =IF(OR(tblMovimientos[[#This Row],[Cantidad]]="",tblMovimientos[[#This Row],[FactorStock]]=""),"",IF(ISNUMBER(tblMovimientos[[#This Row],[Cantidad]]),tblMovimientos[[#This Row],[Cantidad]]*tblMovimientos[[#This Row],[FactorStock]],"")) | L11: =IF(tblMovimientos[[#This Row],[CantidadNeta]]="","",SUMIFS(INDEX(tblMovimientos[CantidadNeta],1):tblMovimientos[[#This Row],[CantidadNeta]],INDEX(tblMovimientos[SKU],1):tblMovimientos[[#This Row],[SKU]],tblMovimientos[[#This Row],[SKU]])) | M11: =IF((tblMovimientos[[#This Row],[Fecha]]&tblMovimientos[[#This Row],[Tipo]]&tblMovimientos[[#This Row],[Producto]]&tblMovimientos[[#This Row],[Cantidad]])="","",IF(OR(tblMovimientos[[#This Row],[Fecha]]="",tblMovimientos[[#This Row],[Tipo]]="",tblMovimientos[[#This Row],[Producto]]="",tblMovimientos[[#This Row],[Cantidad]]="",tblMovimientos[[#This Row],[Responsable]]=""),"⚠ Incompleto",IF(tblMovimientos[[#This Row],[Unidad]]="?","✖ Producto no existe",IF(tblMovimientos[[#This Row],[FactorStock]]=0,"✖ Tipo no válido",IF(NOT(ISNUMBER(tblMovimientos[[#This Row],[Cantidad]])),"✖ Cantidad inválida",IF(tblMovimientos[[#This Row],[Cantidad]]<=0,"✖ Cantidad inválida",IF(AND(tblMovimientos[[#This Row],[Categoría]]<>"",tblMovimientos[[#This Row],[Categoría]]<>INDEX(tblProductos[Categoría],MATCH(tblMovimientos[[#This Row],[SKU]],tblProductos[SKU],0))),"⚠ Categoría no coincide",IF(tblMovimientos[[#This Row],[Saldo]]<0,"✖ Stock insuficiente",IF(AND(LEFT(tblMovimientos[[#This Row],[Tipo]],6)="AJUSTE",tblMovimientos[[#This Row],[Observaciones]]=""),"⚠ Justifique el ajuste","✔ Registrado")))))))))
B12: =IF((tblMovimientos[[#This Row],[Fecha]]&tblMovimientos[[#This Row],[Tipo]]&tblMovimientos[[#This Row],[Producto]]&tblMovimientos[[#This Row],[Cantidad]])="","",ROW()-ROW(tblMovimientos[#Headers])) | G12: =IF(tblMovimientos[[#This Row],[Producto]]="","",TRIM(LEFT(tblMovimientos[[#This Row],[Producto]],FIND(" · ",tblMovimientos[[#This Row],[Producto]]&" · ")-1))) | H12: =IF(tblMovimientos[[#This Row],[SKU]]="","",IFERROR(INDEX(tblProductos[Unidad],MATCH(tblMovimientos[[#This Row],[SKU]],tblProductos[SKU],0)),"?")) | J12: =IF(tblMovimientos[[#This Row],[Tipo]]="","",IFERROR(INDEX(tblTiposMov[FactorStock],MATCH(tblMovimientos[[#This Row],[Tipo]],tblTiposMov[Tipo],0)),0)) | K12: =IF(OR(tblMovimientos[[#This Row],[Cantidad]]="",tblMovimientos[[#This Row],[FactorStock]]=""),"",IF(ISNUMBER(tblMovimientos[[#This Row],[Cantidad]]),tblMovimientos[[#This Row],[Cantidad]]*tblMovimientos[[#This Row],[FactorStock]],"")) | L12: =IF(tblMovimientos[[#This Row],[CantidadNeta]]="","",SUMIFS(INDEX(tblMovimientos[CantidadNeta],1):tblMovimientos[[#This Row],[CantidadNeta]],INDEX(tblMovimientos[SKU],1):tblMovimientos[[#This Row],[SKU]],tblMovimientos[[#This Row],[SKU]])) | M12: =IF((tblMovimientos[[#This Row],[Fecha]]&tblMovimientos[[#This Row],[Tipo]]&tblMovimientos[[#This Row],[Producto]]&tblMovimientos[[#This Row],[Cantidad]])="","",IF(OR(tblMovimientos[[#This Row],[Fecha]]="",tblMovimientos[[#This Row],[Tipo]]="",tblMovimientos[[#This Row],[Producto]]="",tblMovimientos[[#This Row],[Cantidad]]="",tblMovimientos[[#This Row],[Responsable]]=""),"⚠ Incompleto",IF(tblMovimientos[[#This Row],[Unidad]]="?","✖ Producto no existe",IF(tblMovimientos[[#This Row],[FactorStock]]=0,"✖ Tipo no válido",IF(NOT(ISNUMBER(tblMovimientos[[#This Row],[Cantidad]])),"✖ Cantidad inválida",IF(tblMovimientos[[#This Row],[Cantidad]]<=0,"✖ Cantidad inválida",IF(AND(tblMovimientos[[#This Row],[Categoría]]<>"",tblMovimientos[[#This Row],[Categoría]]<>INDEX(tblProductos[Categoría],MATCH(tblMovimientos[[#This Row],[SKU]],tblProductos[SKU],0))),"⚠ Categoría no coincide",IF(tblMovimientos[[#This Row],[Saldo]]<0,"✖ Stock insuficiente",IF(AND(LEFT(tblMovimientos[[#This Row],[Tipo]],6)="AJUSTE",tblMovimientos[[#This Row],[Observaciones]]=""),"⚠ Justifique el ajuste","✔ Registrado")))))))))
B13: =IF((tblMovimientos[[#This Row],[Fecha]]&tblMovimientos[[#This Row],[Tipo]]&tblMovimientos[[#This Row],[Producto]]&tblMovimientos[[#This Row],[Cantidad]])="","",ROW()-ROW(tblMovimientos[#Headers])) | G13: =IF(tblMovimientos[[#This Row],[Producto]]="","",TRIM(LEFT(tblMovimientos[[#This Row],[Producto]],FIND(" · ",tblMovimientos[[#This Row],[Producto]]&" · ")-1))) | H13: =IF(tblMovimientos[[#This Row],[SKU]]="","",IFERROR(INDEX(tblProductos[Unidad],MATCH(tblMovimientos[[#This Row],[SKU]],tblProductos[SKU],0)),"?")) | J13: =IF(tblMovimientos[[#This Row],[Tipo]]="","",IFERROR(INDEX(tblTiposMov[FactorStock],MATCH(tblMovimientos[[#This Row],[Tipo]],tblTiposMov[Tipo],0)),0)) | K13: =IF(OR(tblMovimientos[[#This Row],[Cantidad]]="",tblMovimientos[[#This Row],[FactorStock]]=""),"",IF(ISNUMBER(tblMovimientos[[#This Row],[Cantidad]]),tblMovimientos[[#This Row],[Cantidad]]*tblMovimientos[[#This Row],[FactorStock]],"")) | L13: =IF(tblMovimientos[[#This Row],[CantidadNeta]]="","",SUMIFS(INDEX(tblMovimientos[CantidadNeta],1):tblMovimientos[[#This Row],[CantidadNeta]],INDEX(tblMovimientos[SKU],1):tblMovimientos[[#This Row],[SKU]],tblMovimientos[[#This Row],[SKU]])) | M13: =IF((tblMovimientos[[#This Row],[Fecha]]&tblMovimientos[[#This Row],[Tipo]]&tblMovimientos[[#This Row],[Producto]]&tblMovimientos[[#This Row],[Cantidad]])="","",IF(OR(tblMovimientos[[#This Row],[Fecha]]="",tblMovimientos[[#This Row],[Tipo]]="",tblMovimientos[[#This Row],[Producto]]="",tblMovimientos[[#This Row],[Cantidad]]="",tblMovimientos[[#This Row],[Responsable]]=""),"⚠ Incompleto",IF(tblMovimientos[[#This Row],[Unidad]]="?","✖ Producto no existe",IF(tblMovimientos[[#This Row],[FactorStock]]=0,"✖ Tipo no válido",IF(NOT(ISNUMBER(tblMovimientos[[#This Row],[Cantidad]])),"✖ Cantidad inválida",IF(tblMovimientos[[#This Row],[Cantidad]]<=0,"✖ Cantidad inválida",IF(AND(tblMovimientos[[#This Row],[Categoría]]<>"",tblMovimientos[[#This Row],[Categoría]]<>INDEX(tblProductos[Categoría],MATCH(tblMovimientos[[#This Row],[SKU]],tblProductos[SKU],0))),"⚠ Categoría no coincide",IF(tblMovimientos[[#This Row],[Saldo]]<0,"✖ Stock insuficiente",IF(AND(LEFT(tblMovimientos[[#This Row],[Tipo]],6)="AJUSTE",tblMovimientos[[#This Row],[Observaciones]]=""),"⚠ Justifique el ajuste","✔ Registrado")))))))))
B14: =IF((tblMovimientos[[#This Row],[Fecha]]&tblMovimientos[[#This Row],[Tipo]]&tblMovimientos[[#This Row],[Producto]]&tblMovimientos[[#This Row],[Cantidad]])="","",ROW()-ROW(tblMovimientos[#Headers])) | G14: =IF(tblMovimientos[[#This Row],[Producto]]="","",TRIM(LEFT(tblMovimientos[[#This Row],[Producto]],FIND(" · ",tblMovimientos[[#This Row],[Producto]]&" · ")-1))) | H14: =IF(tblMovimientos[[#This Row],[SKU]]="","",IFERROR(INDEX(tblProductos[Unidad],MATCH(tblMovimientos[[#This Row],[SKU]],tblProductos[SKU],0)),"?")) | J14: =IF(tblMovimientos[[#This Row],[Tipo]]="","",IFERROR(INDEX(tblTiposMov[FactorStock],MATCH(tblMovimientos[[#This Row],[Tipo]],tblTiposMov[Tipo],0)),0)) | K14: =IF(OR(tblMovimientos[[#This Row],[Cantidad]]="",tblMovimientos[[#This Row],[FactorStock]]=""),"",IF(ISNUMBER(tblMovimientos[[#This Row],[Cantidad]]),tblMovimientos[[#This Row],[Cantidad]]*tblMovimientos[[#This Row],[FactorStock]],"")) | L14: =IF(tblMovimientos[[#This Row],[CantidadNeta]]="","",SUMIFS(INDEX(tblMovimientos[CantidadNeta],1):tblMovimientos[[#This Row],[CantidadNeta]],INDEX(tblMovimientos[SKU],1):tblMovimientos[[#This Row],[SKU]],tblMovimientos[[#This Row],[SKU]])) | M14: =IF((tblMovimientos[[#This Row],[Fecha]]&tblMovimientos[[#This Row],[Tipo]]&tblMovimientos[[#This Row],[Producto]]&tblMovimientos[[#This Row],[Cantidad]])="","",IF(OR(tblMovimientos[[#This Row],[Fecha]]="",tblMovimientos[[#This Row],[Tipo]]="",tblMovimientos[[#This Row],[Producto]]="",tblMovimientos[[#This Row],[Cantidad]]="",tblMovimientos[[#This Row],[Responsable]]=""),"⚠ Incompleto",IF(tblMovimientos[[#This Row],[Unidad]]="?","✖ Producto no existe",IF(tblMovimientos[[#This Row],[FactorStock]]=0,"✖ Tipo no válido",IF(NOT(ISNUMBER(tblMovimientos[[#This Row],[Cantidad]])),"✖ Cantidad inválida",IF(tblMovimientos[[#This Row],[Cantidad]]<=0,"✖ Cantidad inválida",IF(AND(tblMovimientos[[#This Row],[Categoría]]<>"",tblMovimientos[[#This Row],[Categoría]]<>INDEX(tblProductos[Categoría],MATCH(tblMovimientos[[#This Row],[SKU]],tblProductos[SKU],0))),"⚠ Categoría no coincide",IF(tblMovimientos[[#This Row],[Saldo]]<0,"✖ Stock insuficiente",IF(AND(LEFT(tblMovimientos[[#This Row],[Tipo]],6)="AJUSTE",tblMovimientos[[#This Row],[Observaciones]]=""),"⚠ Justifique el ajuste","✔ Registrado")))))))))
B15: =IF((tblMovimientos[[#This Row],[Fecha]]&tblMovimientos[[#This Row],[Tipo]]&tblMovimientos[[#This Row],[Producto]]&tblMovimientos[[#This Row],[Cantidad]])="","",ROW()-ROW(tblMovimientos[#Headers])) | G15: =IF(tblMovimientos[[#This Row],[Producto]]="","",TRIM(LEFT(tblMovimientos[[#This Row],[Producto]],FIND(" · ",tblMovimientos[[#This Row],[Producto]]&" · ")-1))) | H15: =IF(tblMovimientos[[#This Row],[SKU]]="","",IFERROR(INDEX(tblProductos[Unidad],MATCH(tblMovimientos[[#This Row],[SKU]],tblProductos[SKU],0)),"?")) | J15: =IF(tblMovimientos[[#This Row],[Tipo]]="","",IFERROR(INDEX(tblTiposMov[FactorStock],MATCH(tblMovimientos[[#This Row],[Tipo]],tblTiposMov[Tipo],0)),0)) | K15: =IF(OR(tblMovimientos[[#This Row],[Cantidad]]="",tblMovimientos[[#This Row],[FactorStock]]=""),"",IF(ISNUMBER(tblMovimientos[[#This Row],[Cantidad]]),tblMovimientos[[#This Row],[Cantidad]]*tblMovimientos[[#This Row],[FactorStock]],"")) | L15: =IF(tblMovimientos[[#This Row],[CantidadNeta]]="","",SUMIFS(INDEX(tblMovimientos[CantidadNeta],1):tblMovimientos[[#This Row],[CantidadNeta]],INDEX(tblMovimientos[SKU],1):tblMovimientos[[#This Row],[SKU]],tblMovimientos[[#This Row],[SKU]])) | M15: =IF((tblMovimientos[[#This Row],[Fecha]]&tblMovimientos[[#This Row],[Tipo]]&tblMovimientos[[#This Row],[Producto]]&tblMovimientos[[#This Row],[Cantidad]])="","",IF(OR(tblMovimientos[[#This Row],[Fecha]]="",tblMovimientos[[#This Row],[Tipo]]="",tblMovimientos[[#This Row],[Producto]]="",tblMovimientos[[#This Row],[Cantidad]]="",tblMovimientos[[#This Row],[Responsable]]=""),"⚠ Incompleto",IF(tblMovimientos[[#This Row],[Unidad]]="?","✖ Producto no existe",IF(tblMovimientos[[#This Row],[FactorStock]]=0,"✖ Tipo no válido",IF(NOT(ISNUMBER(tblMovimientos[[#This Row],[Cantidad]])),"✖ Cantidad inválida",IF(tblMovimientos[[#This Row],[Cantidad]]<=0,"✖ Cantidad inválida",IF(AND(tblMovimientos[[#This Row],[Categoría]]<>"",tblMovimientos[[#This Row],[Categoría]]<>INDEX(tblProductos[Categoría],MATCH(tblMovimientos[[#This Row],[SKU]],tblProductos[SKU],0))),"⚠ Categoría no coincide",IF(tblMovimientos[[#This Row],[Saldo]]<0,"✖ Stock insuficiente",IF(AND(LEFT(tblMovimientos[[#This Row],[Tipo]],6)="AJUSTE",tblMovimientos[[#This Row],[Observaciones]]=""),"⚠ Justifique el ajuste","✔ Registrado")))))))))
